Workbook

Sheet Table
A1: # | B1: 性質 | C1: 表單 | D1: 用途 | E1: Remarks
A2: 1 | B2: 資料參考 | C2: 合作品項資料表
B3: 稽核報表 | C3: 合作品項數量控管表 | D3: 品項數量保留多少給級別，多少可以單賣，多少正在洽談中。 | E3: 保留期限的設置以及自動放棄。
B4: 資料輸入 | C4: 客戶資料表
B5: 資料輸入 | C5: 客戶合作品項資料表 | D5: 輸入與管理級別各區域選取數量資料 | E5: 價格計算、合約產生，級別區域項目數量檢核。
B6: 資料輸入 | C6: 候補名單
B7: 資料輸入 | C7: 合作狀態表 | D7: 洽談、簽約、收款
B8: 資料輸入 | C8: 品項執行狀態表
B11: 階段 | C11: 任務 | D11: 說明 | E11: 備註
A12: 1 | B12: 洽談 | C12: [業務] 與贊助商接洽。 | E12: Booking 原訂合作品項。
A13: 2 | B13: 確認品項 | C13: [業務] 與贊助商確認合作內容。 | D13: 確認後寄 email 給客戶 cc 給 bc@。
A14: 3 | B14: 出合約 | C14: [PM] 由 bc.pm 製作合約，業務寄出。
A15: 4 | B15: 追合約 | C15: [PM] 第一次提醒：一個月 | D15: 每一週提醒一次，提醒兩次還沒交就到商合群組確認繼續等還是釋出。 | E15: 釋出原訂合作品項。
A16: 5 | B16: 合約用印 | C16: [秘書處] 雙方合約用印
A17: 6 | B17: 合約存檔 | C17: [秘書處] 群掃描上傳、歸檔
A18: 7 | B18: 更新合作狀態
A19: 8 | B19: 追蹤付款狀態 | C19: [PM] 追蹤贊助商付款狀態。 | D19: 確認付款後更新付款狀態。
A20: 9 | B20: 追蹤後續品項執行 | C20: [業務] 追蹤合作品項執行狀態。 | D20: 確認執行後更新執行狀態。
A21: 10 | B21: 結案 | D21: 確認完成後更新合作狀態。

Sheet 統計圖表
A1: 贊助商數量與金額統計 | G1: 合約狀態統計 | J1: 付款狀態統計 | M1: 友善飯店專案 | P1: 彩虹市集專案
A2: 級別 | B2: 贊助商數量 | C2: 合約金額 | D2: 現金金額 | E2: 商品金額 | G2: 項目 | H2: 贊助商數量 | J2: 項目 | K2: 贊助商數量 | M2: 專案 | N2: 贊助商數量 | P2: =IFERROR(__xludf.DUMMYFUNCTION("QUERY(IMPORTRANGE(""https://docs.google.com/spreadsheets/d/1TzBxi33SqU_nLx60nOWWbFcrtCUmq1B_2rgPywrfN0s/"",""'參與攤位'!A1:G""), ""SELECT Col1, Col2, Col3, Col4,Col7"", 1)"),"分區") -> 分區 | Q2: =IFERROR(__xludf.DUMMYFUNCTION("""COMPUTED_VALUE"""),"一般市集攤位") -> 一般市集攤位 | R2: =IFERROR(__xludf.DUMMYFUNCTION("""COMPUTED_VALUE"""),"級別攤位") -> 級別攤位 | S2: =IFERROR(__xludf.DUMMYFUNCTION("""COMPUTED_VALUE"""),"分區攤位數") -> 分區攤位數 | T2: =IFERROR(__xludf.DUMMYFUNCTION("""COMPUTED_VALUE"""),"預估收入") -> 預估收入
A3: 白金級 | B3: =COUNTIFS('31業務統計總表'!J$2:T$2,$A3,'31業務統計總表'!J$3:T$3,"<>") -> 0 | C3: =SUMIFS('31業務統計總表'!J$57:T$57,'31業務統計總表'!J$2:T$2,$A3,'31業務統計總表'!J$3:T$3,"<>") -> 0 | D3: =SUMIFS('31業務統計總表'!J$58:T$58,'31業務統計總表'!J$2:T$2,$A3,'31業務統計總表'!J$3:T$3,"<>") -> 0 | E3: =SUMIFS('31業務統計總表'!J$59:T$59,'31業務統計總表'!J$2:T$2,$A3,'31業務統計總表'!J$3:T$3,"<>") -> 0 | G3: 洽談中 | H3: =COUNTIFS('31業務統計總表'!J$3:T$3,"<>",'31業務統計總表'!J$61:T$61,"*" & $G3) -> 0 | J3: 待付款 | K3: =COUNTIFS('31業務統計總表'!J$3:T$3,"<>",'31業務統計總表'!J$62:T$62,"*" & $J3) -> 2 | M3: A | N3: =COUNTIFS('31業務統計總表'!J$2:T$2,"友善飯店",'31業務統計總表'!J$3:T$3,"<>",'31業務統計總表'!J$4:T$4,"A") -> 2 | P3: =IFERROR(__xludf.DUMMYFUNCTION("""COMPUTED_VALUE"""),"夜色") -> 夜色 | Q3: =IFERROR(__xludf.DUMMYFUNCTION("""COMPUTED_VALUE"""),5.0) -> 5 | R3: =IFERROR(__xludf.DUMMYFUNCTION("""COMPUTED_VALUE"""),5.0) -> 5 | S3: =IFERROR(__xludf.DUMMYFUNCTION("""COMPUTED_VALUE"""),10.0) -> 10 | T3: =IFERROR(__xludf.DUMMYFUNCTION("""COMPUTED_VALUE"""),100000.0) -> 100000
A4: 黃金級 | B4: =COUNTIFS('31業務統計總表'!J$2:T$2,$A4,'31業務統計總表'!J$3:T$3,"<>") -> 0 | C4: =SUMIFS('31業務統計總表'!J$57:T$57,'31業務統計總表'!J$2:T$2,$A4,'31業務統計總表'!J$3:T$3,"<>") -> 0 | D4: =SUMIFS('31業務統計總表'!J$58:T$58,'31業務統計總表'!J$2:T$2,$A4,'31業務統計總表'!J$3:T$3,"<>") -> 0 | E4: =SUMIFS('31業務統計總表'!J$59:T$59,'31業務統計總表'!J$2:T$2,$A4,'31業務統計總表'!J$3:T$3,"<>") -> 0 | G4: 製作中 | H4: =COUNTIFS('31業務統計總表'!J$3:T$3,"<>",'31業務統計總表'!J$61:T$61,"*" & $G4) -> 0 | J4: 已付款 | K4: =COUNTIFS('31業務統計總表'!J$3:T$3,"<>",'31業務統計總表'!J$62:T$62,"*" & $J4) -> 37 | M4: B | N4: =COUNTIFS('31業務統計總表'!J$2:T$2,"友善飯店",'31業務統計總表'!J$3:T$3,"<>",'31業務統計總表'!J$4:T$4,"B") -> 6 | P4: =IFERROR(__xludf.DUMMYFUNCTION("""COMPUTED_VALUE"""),"時尚") -> 時尚 | Q4: =IFERROR(__xludf.DUMMYFUNCTION("""COMPUTED_VALUE"""),19.0) -> 19 | R4: =IFERROR(__xludf.DUMMYFUNCTION("""COMPUTED_VALUE"""),4.0) -> 4 | S4: =IFERROR(__xludf.DUMMYFUNCTION("""COMPUTED_VALUE"""),23.0) -> 23 | T4: =IFERROR(__xludf.DUMMYFUNCTION("""COMPUTED_VALUE"""),380000.0) -> 380000
A5: 鈦金級 | B5: =COUNTIFS('31業務統計總表'!J$2:T$2,$A5,'31業務統計總表'!J$3:T$3,"<>") -> 4 | C5: =SUMIFS('31業務統計總表'!J$57:T$57,'31業務統計總表'!J$2:T$2,$A5,'31業務統計總表'!J$3:T$3,"<>") -> 1715000 | D5: =SUMIFS('31業務統計總表'!J$58:T$58,'31業務統計總表'!J$2:T$2,$A5,'31業務統計總表'!J$3:T$3,"<>") -> 1715000 | E5: =SUMIFS('31業務統計總表'!J$59:T$59,'31業務統計總表'!J$2:T$2,$A5,'31業務統計總表'!J$3:T$3,"<>") -> 0 | G5: 待簽回 | H5: =COUNTIFS('31業務統計總表'!J$3:T$3,"<>",'31業務統計總表'!J$61:T$61,"*" & $G5) -> 0 | J5: 未標記 | K5: =COUNTIFS('31業務統計總表'!J$3:T$3,"<>",'31業務統計總表'!J$62:T$62,"") -> 19 | M5: C | N5: =COUNTIFS('31業務統計總表'!J$2:T$2,"友善飯店",'31業務統計總表'!J$3:T$3,"<>",'31業務統計總表'!J$4:T$4,"C") -> 7 | P5: =IFERROR(__xludf.DUMMYFUNCTION("""COMPUTED_VALUE"""),"生活") -> 生活 | Q5: =IFERROR(__xludf.DUMMYFUNCTION("""COMPUTED_VALUE"""),12.0) -> 12 | R5: =IFERROR(__xludf.DUMMYFUNCTION("""COMPUTED_VALUE"""),6.0) -> 6 | S5: =IFERROR(__xludf.DUMMYFUNCTION("""COMPUTED_VALUE"""),18.0) -> 18 | T5: =IFERROR(__xludf.DUMMYFUNCTION("""COMPUTED_VALUE"""),240000.0) -> 240000
A6: 銀級 | B6: =COUNTIFS('31業務統計總表'!J$2:T$2,$A6,'31業務統計總表'!J$3:T$3,"<>") -> 12 | C6: =SUMIFS('31業務統計總表'!J$57:T$57,'31業務統計總表'!J$2:T$2,$A6,'31業務統計總表'!J$3:T$3,"<>") -> 2492000 | D6: =SUMIFS('31業務統計總表'!J$58:T$58,'31業務統計總表'!J$2:T$2,$A6,'31業務統計總表'!J$3:T$3,"<>") -> 2388000 | E6: =SUMIFS('31業務統計總表'!J$59:T$59,'31業務統計總表'!J$2:T$2,$A6,'31業務統計總表'!J$3:T$3,"<>") -> 104000 | G6: 已簽回 | H6: =COUNTIFS('31業務統計總表'!J$3:T$3,"<>",'31業務統計總表'!J$61:T$61,"*" & $G6) -> 54 | J6: 總計 | K6: =SUM(K3:K5) -> 58 | M6: 總計 | N6: =SUM(N3:N5) -> 15 | P6: =IFERROR(__xludf.DUMMYFUNCTION("""COMPUTED_VALUE"""),"醫療") -> 醫療 | Q6: =IFERROR(__xludf.DUMMYFUNCTION("""COMPUTED_VALUE"""),8.0) -> 8 | R6: =IFERROR(__xludf.DUMMYFUNCTION("""COMPUTED_VALUE"""),3.0) -> 3 | S6: =IFERROR(__xludf.DUMMYFUNCTION("""COMPUTED_VALUE"""),11.0) -> 11 | T6: =IFERROR(__xludf.DUMMYFUNCTION("""COMPUTED_VALUE"""),160000.0) -> 160000
A7: 銅級 | B7: =COUNTIFS('31業務統計總表'!J$2:T$2,$A7,'31業務統計總表'!J$3:T$3,"<>") -> 6 | C7: =SUMIFS('31業務統計總表'!J$57:T$57,'31業務統計總表'!J$2:T$2,$A7,'31業務統計總表'!J$3:T$3,"<>") -> 708000 | D7: =SUMIFS('31業務統計總表'!J$58:T$58,'31業務統計總表'!J$2:T$2,$A7,'31業務統計總表'!J$3:T$3,"<>") -> 600000 | E7: =SUMIFS('31業務統計總表'!J$59:T$59,'31業務統計總表'!J$2:T$2,$A7,'31業務統計總表'!J$3:T$3,"<>") -> 108000 | G7: 未填寫 | H7: =COUNTIFS('31業務統計總表'!J$3:T$3,"<>",'31業務統計總表'!J$61:T$61,"") -> 4 | P7: =IFERROR(__xludf.DUMMYFUNCTION("""COMPUTED_VALUE"""),"多元") -> 多元 | Q7: =IFERROR(__xludf.DUMMYFUNCTION("""COMPUTED_VALUE"""),0.0) -> 0 | R7: =IFERROR(__xludf.DUMMYFUNCTION("""COMPUTED_VALUE"""),4.0) -> 4 | S7: =IFERROR(__xludf.DUMMYFUNCTION("""COMPUTED_VALUE"""),4.0) -> 4 | T7: =IFERROR(__xludf.DUMMYFUNCTION("""COMPUTED_VALUE"""),0.0) -> 0
A8: 花車 | B8: =COUNTIFS('31業務統計總表'!J$2:T$2,$A8,'31業務統計總表'!J$3:T$3,"<>") -> 9 | C8: =SUMIFS('31業務統計總表'!J$57:T$57,'31業務統計總表'!J$2:T$2,$A8,'31業務統計總表'!J$3:T$3,"<>") -> 1310000 | D8: =SUMIFS('31業務統計總表'!J$58:T$58,'31業務統計總表'!J$2:T$2,$A8,'31業務統計總表'!J$3:T$3,"<>") -> 1310000 | E8: =SUMIFS('31業務統計總表'!J$59:T$59,'31業務統計總表'!J$2:T$2,$A8,'31業務統計總表'!J$3:T$3,"<>") -> 0 | G8: 總計 | H8: =SUM(H3:H7) -> 58 | J8: 非市集已付款金額 | K8: =sumif('31業務統計總表'!J62:T62,"1. 已付款",'31業務統計總表'!J58:T58) -> 6251000 | P8: =IFERROR(__xludf.DUMMYFUNCTION("""COMPUTED_VALUE"""),"文創") -> 文創 | Q8: =IFERROR(__xludf.DUMMYFUNCTION("""COMPUTED_VALUE"""),7.5) -> 7.5 | R8: =IFERROR(__xludf.DUMMYFUNCTION("""COMPUTED_VALUE"""),0.0) -> 0 | S8: =IFERROR(__xludf.DUMMYFUNCTION("""COMPUTED_VALUE"""),7.5) -> 7.5 | T8: =IFERROR(__xludf.DUMMYFUNCTION("""COMPUTED_VALUE"""),150000.0) -> 150000
A9: 單買 | B9: =COUNTIFS('31業務統計總表'!J$2:T$2,$A9,'31業務統計總表'!J$3:T$3,"<>") -> 7 | C9: =SUMIFS('31業務統計總表'!J$57:T$57,'31業務統計總表'!J$2:T$2,$A9,'31業務統計總表'!J$3:T$3,"<>") -> 509000 | D9: =SUMIFS('31業務統計總表'!J$58:T$58,'31業務統計總表'!J$2:T$2,$A9,'31業務統計總表'!J$3:T$3,"<>") -> 466000 | E9: =SUMIFS('31業務統計總表'!J$59:T$59,'31業務統計總表'!J$2:T$2,$A9,'31業務統計總表'!J$3:T$3,"<>") -> 43000 | J9: 市集已付款金額 | K9: =1077500+22000 -> 1099500 | P9: =IFERROR(__xludf.DUMMYFUNCTION("""COMPUTED_VALUE"""),"喝水") -> 喝水 | Q9: =IFERROR(__xludf.DUMMYFUNCTION("""COMPUTED_VALUE"""),0.0) -> 0 | R9: =IFERROR(__xludf.DUMMYFUNCTION("""COMPUTED_VALUE"""),2.0) -> 2 | S9: =IFERROR(__xludf.DUMMYFUNCTION("""COMPUTED_VALUE"""),2.0) -> 2 | T9: =IFERROR(__xludf.DUMMYFUNCTION("""COMPUTED_VALUE"""),0.0) -> 0
A10: 其他 | B10: =COUNTIFS('31業務統計總表'!J$2:T$2,$A10,'31業務統計總表'!J$3:T$3,"<>")+countIFs('31業務統計總表'!J$2:T$2,"市集",'31業務統計總表'!J$3:T$3,"<>") -> 6 | C10: =SUMIFS('31業務統計總表'!J$57:T$57,'31業務統計總表'!J$2:T$2,$A10,'31業務統計總表'!J$3:T$3,"<>") -> 240000 | D10: =SUMIFS('31業務統計總表'!J$58:T$58,'31業務統計總表'!J$2:T$2,$A10,'31業務統計總表'!J$3:T$3,"<>")+SUMIFS('31業務統計總表'!J$58:T$58,'31業務統計總表'!J$2:T$2,"市集",'31業務統計總表'!J$3:T$3,"<>") -> 160000 | E10: =SUMIFS('31業務統計總表'!J$59:T$59,'31業務統計總表'!J$2:T$2,$A10,'31業務統計總表'!J$3:T$3,"<>") -> 80000 | J10: 總計已付款金額 | K10: =sum(K8:K9) -> 7350500 | P10: =IFERROR(__xludf.DUMMYFUNCTION("""COMPUTED_VALUE"""),"一般商業攤位（全攤）") -> 一般商業攤位（全攤） | S10: =IFERROR(__xludf.DUMMYFUNCTION("""COMPUTED_VALUE"""),44.0) -> 44 | T10: =IFERROR(__xludf.DUMMYFUNCTION("""COMPUTED_VALUE"""),1021000.0) -> 1021000
A11: 友善飯店 | B11: =COUNTIFS('31業務統計總表'!J$2:T$2,$A11,'31業務統計總表'!J$3:T$3,"<>") -> 15 | C11: =SUMIFS('31業務統計總表'!J$57:T$57,'31業務統計總表'!J$2:T$2,$A11,'31業務統計總表'!J$3:T$3,"<>") -> 300000 | D11: =SUMIFS('31業務統計總表'!J$58:T$58,'31業務統計總表'!J$2:T$2,$A11,'31業務統計總表'!J$3:T$3,"<>") -> 35000 | E11: =SUMIFS('31業務統計總表'!J$59:T$59,'31業務統計總表'!J$2:T$2,$A11,'31業務統計總表'!J$3:T$3,"<>") -> 265000 | P11: =IFERROR(__xludf.DUMMYFUNCTION("""COMPUTED_VALUE"""),"一般商業攤位（半攤）") -> 一般商業攤位（半攤） | S11: =IFERROR(__xludf.DUMMYFUNCTION("""COMPUTED_VALUE"""),6.0) -> 6
A12: 彩虹市集 | B12: =Q10 | C12: 1224000 | D12: =C12-E12 -> 1224000 | E12: 0 | P12: =IFERROR(__xludf.DUMMYFUNCTION("""COMPUTED_VALUE"""),"級別商業攤位") -> 級別商業攤位 | S12: =IFERROR(__xludf.DUMMYFUNCTION("""COMPUTED_VALUE"""),24.0) -> 24
A13: 總計 | B13: =SUM(B3:B12) -> 59 | C13: =SUM(C3:C12) -> 8498000 | D13: =SUM(D3:D12) -> 7898000 | E13: =SUM(E3:E12) -> 600000 | P13: =IFERROR(__xludf.DUMMYFUNCTION("""COMPUTED_VALUE"""),"公益攤位") -> 公益攤位 | S13: =IFERROR(__xludf.DUMMYFUNCTION("""COMPUTED_VALUE"""),28.0) -> 28 | T13: =IFERROR(__xludf.DUMMYFUNCTION("""COMPUTED_VALUE"""),196000.0) -> 196000
P14: =IFERROR(__xludf.DUMMYFUNCTION("""COMPUTED_VALUE"""),"免費攤位") -> 免費攤位 | S14: =IFERROR(__xludf.DUMMYFUNCTION("""COMPUTED_VALUE"""),7.0) -> 7
P15: =IFERROR(__xludf.DUMMYFUNCTION("""COMPUTED_VALUE"""),"全部攤位") -> 全部攤位 | S15: =IFERROR(__xludf.DUMMYFUNCTION("""COMPUTED_VALUE"""),109.0) -> 109 | T15: =IFERROR(__xludf.DUMMYFUNCTION("""COMPUTED_VALUE"""),1217000.0) -> 1217000

Sheet 32收款對帳表
E1: 商合會計對帳區 | I1: 廠商匯款資訊填寫資料區 | L1: 廠商財務憑證資訊區 | T1: 廠商合約資訊填寫資料區 | Z1: 保證金退款填寫資料區
A2: 贊助商/單位名稱 | B2: 聯絡人 | C2: 商合組窗口 | D2: 業務屬性 | E2: 帳戶 | F2: 日期 | G2: 金額 | H2: 備註 | I2: 預計匯款日 | J2: 預計匯款金額 | K2: 匯款帳號末五碼 | L2: 憑證類型 | M2: 憑證編號 | N2: 憑證日期 | O2: 發票金額 | P2: 品名 | Q2: 憑證抬頭 | R2: 憑證統一編號 | S2: 憑證寄出 | T2: 合約收件人 | U2: 合約收件人電話 | V2: 合約收件人地址 | W2: 合約寄出 | X2: 合約用印 | Y2: 合約存檔 | Z2: 退款日期 | AA2: 退款金額 | AB2: 退款銀行代碼 | AC2: 退款帳號 | AD2: 退款戶名 | AE2: 備註 | AF2: 退款備註
A3: AAA公司 | B3: BBBB窗口 | C3: CCCC窗口 | D3: NGO花車 | F3: MM/DD | G3: $$$$$ | I3: MM/DD | J3: $$$$$ | K3: DDDDD | L3: 發票 | M3: XXXXX1 | N3: YY/MM/DD | O3: $$$$$ | P3: XXX執行 | Q3: AAA公司 | R3: 39759641 | S3: FFFFFF@gmail.com | T3: BBBB窗口 | U3: 09TT-TTTTTT | V3: EE市EE區EE路EE號EE樓 | W3: FFFFFF@gmail.com | Y3: docs.google.com
A4: LesPark | B4: 雪靖 | C4: 深紅 | D4: 各類廣告 | E4: 台幣帳戶 | F4: 45124 | G4: 180000 | H4: v | I4: 45124 | J4: 180000 | K4: 01324 | L4: 發票 | M4: RJ17391754 | N4: 45135 | O4: 180000 | P4: 遊行贊助執行 | Q4: 貝里斯商艾虎網路科技有限公司台灣分公司 | R4: 24811205 | S4: tttishu95@taiwanpride.lgbt

Sheet 付款追蹤
A1: =COUNTA(A3:A525) -> 2 | B1: =COUNTA(B3:B525) -> 38
A2: 待付款 | B2: 已付款
A3: =IFERROR(__xludf.DUMMYFUNCTION("QUERY(TRANSPOSE({'31業務統計總表'!B3:J3;'31業務統計總表'!B62:J62}), ""SELECT Col1 WHERE Col2 LIKE '0. %'"", 0)"),"GSK") -> GSK | B3: =IFERROR(__xludf.DUMMYFUNCTION("QUERY(TRANSPOSE({'31業務統計總表'!B3:J3;'31業務統計總表'!B62:J62}), ""SELECT Col1 WHERE Col2 LIKE '1. %'"", 0)"),"波士頓科技") -> 波士頓科技
A4: =IFERROR(__xludf.DUMMYFUNCTION("""COMPUTED_VALUE"""),"必勝客") -> 必勝客 | B4: =IFERROR(__xludf.DUMMYFUNCTION("""COMPUTED_VALUE"""),"諾億保經") -> 諾億保經
B5: =IFERROR(__xludf.DUMMYFUNCTION("""COMPUTED_VALUE"""),"台灣美光") -> 台灣美光
B6: =IFERROR(__xludf.DUMMYFUNCTION("""COMPUTED_VALUE"""),"JINS") -> JINS
B7: =IFERROR(__xludf.DUMMYFUNCTION("""COMPUTED_VALUE"""),"Google") -> Google
B8: =IFERROR(__xludf.DUMMYFUNCTION("""COMPUTED_VALUE"""),"LifeWonders") -> LifeWonders
B9: =IFERROR(__xludf.DUMMYFUNCTION("""COMPUTED_VALUE"""),"Gstar") -> Gstar
B10: =IFERROR(__xludf.DUMMYFUNCTION("""COMPUTED_VALUE"""),"聯合利華") -> 聯合利華
B11: =IFERROR(__xludf.DUMMYFUNCTION("""COMPUTED_VALUE"""),"Johnnie Walker ") -> Johnnie Walker
B12: =IFERROR(__xludf.DUMMYFUNCTION("""COMPUTED_VALUE"""),"Tapestry") -> Tapestry
B13: =IFERROR(__xludf.DUMMYFUNCTION("""COMPUTED_VALUE"""),"臺虎精釀") -> 臺虎精釀
B14: =IFERROR(__xludf.DUMMYFUNCTION("""COMPUTED_VALUE"""),"Lespark") -> Lespark
B15: =IFERROR(__xludf.DUMMYFUNCTION("""COMPUTED_VALUE"""),"吉利亞醫藥") -> 吉利亞醫藥
B16: =IFERROR(__xludf.DUMMYFUNCTION("""COMPUTED_VALUE"""),"AZ") -> AZ
B17: =IFERROR(__xludf.DUMMYFUNCTION("""COMPUTED_VALUE"""),"犀牛盾") -> 犀牛盾
B18: =IFERROR(__xludf.DUMMYFUNCTION("""COMPUTED_VALUE"""),"默沙東") -> 默沙東
B19: =IFERROR(__xludf.DUMMYFUNCTION("""COMPUTED_VALUE"""),"TFC 臺北婦產科診所") -> TFC 臺北婦產科診所
B20: =IFERROR(__xludf.DUMMYFUNCTION("""COMPUTED_VALUE"""),"Hyve") -> Hyve
B21: =IFERROR(__xludf.DUMMYFUNCTION("""COMPUTED_VALUE"""),"疾管署") -> 疾管署
B22: =IFERROR(__xludf.DUMMYFUNCTION("""COMPUTED_VALUE"""),"彩虹酷兒") -> 彩虹酷兒
B23: =IFERROR(__xludf.DUMMYFUNCTION("""COMPUTED_VALUE"""),"渣打銀行") -> 渣打銀行
B24: =IFERROR(__xludf.DUMMYFUNCTION("""COMPUTED_VALUE"""),"VERVE") -> VERVE
B25: =IFERROR(__xludf.DUMMYFUNCTION("""COMPUTED_VALUE"""),"IM Adult") -> IM Adult
B26: =IFERROR(__xludf.DUMMYFUNCTION("""COMPUTED_VALUE"""),"GAP") -> GAP
B27: =IFERROR(__xludf.DUMMYFUNCTION("""COMPUTED_VALUE"""),"Uber Eats") -> Uber Eats
B28: =IFERROR(__xludf.DUMMYFUNCTION("""COMPUTED_VALUE"""),"NIKE") -> NIKE
B29: =IFERROR(__xludf.DUMMYFUNCTION("""COMPUTED_VALUE"""),"TSMC") -> TSMC
B30: =IFERROR(__xludf.DUMMYFUNCTION("""COMPUTED_VALUE"""),"FNF") -> FNF
B31: =IFERROR(__xludf.DUMMYFUNCTION("""COMPUTED_VALUE"""),"可口可樂") -> 可口可樂
B32: =IFERROR(__xludf.DUMMYFUNCTION("""COMPUTED_VALUE"""),"新思科技") -> 新思科技
B33: =IFERROR(__xludf.DUMMYFUNCTION("""COMPUTED_VALUE"""),"愛群婦產科") -> 愛群婦產科
B34: =IFERROR(__xludf.DUMMYFUNCTION("""COMPUTED_VALUE"""),"辻利茶舖") -> 辻利茶舖
B35: =IFERROR(__xludf.DUMMYFUNCTION("""COMPUTED_VALUE"""),"Sagami") -> Sagami
B36: =IFERROR(__xludf.DUMMYFUNCTION("""COMPUTED_VALUE"""),"台灣百健") -> 台灣百健
B37: =IFERROR(__xludf.DUMMYFUNCTION("""COMPUTED_VALUE"""),"華納兄弟") -> 華納兄弟
B38: =IFERROR(__xludf.DUMMYFUNCTION("""COMPUTED_VALUE"""),"聯名商品") -> 聯名商品
B39: =IFERROR(__xludf.DUMMYFUNCTION("""COMPUTED_VALUE"""),"君悅飯店") -> 君悅飯店
B40: =IFERROR(__xludf.DUMMYFUNCTION("""COMPUTED_VALUE"""),"小鹿文娛") -> 小鹿文娛

Sheet 合約管理
A1: =COUNTA(A3:A525) -> 1 | B1: =COUNTA(B3:B525) -> 1 | C1: =COUNTA(C3:C525) -> 1 | D1: =COUNTA(D3:D525) -> 54
A2: 洽談中 | B2: 待製作 | C2: 待簽回 | D2: 已簽回
A3: =IFERROR(__xludf.DUMMYFUNCTION("QUERY(TRANSPOSE({'31業務統計總表'!D1:J3;'31業務統計總表'!D61:J61}), ""SELECT Col3 WHERE Col4 LIKE '0. %'"", 0)"),"#N/A") -> #N/A | B3: =IFERROR(__xludf.DUMMYFUNCTION("QUERY(TRANSPOSE({'31業務統計總表'!D3:J3;'31業務統計總表'!D61:J61}), ""SELECT Col1 WHERE Col2 LIKE '1. %'"", 0)"),"#N/A") -> #N/A | C3: =IFERROR(__xludf.DUMMYFUNCTION("QUERY(TRANSPOSE({'31業務統計總表'!D3:J3;'31業務統計總表'!D61:J61}), ""SELECT Col1 WHERE Col2 LIKE '2. %'"", 0)"),"波士頓科技") -> 波士頓科技 | D3: =IFERROR(__xludf.DUMMYFUNCTION("QUERY(TRANSPOSE({'31業務統計總表'!D3:J3;'31業務統計總表'!D61:J61}), ""SELECT Col1 WHERE Col2 LIKE '3. %'"", 0)"),"諾億保經") -> 諾億保經
D4: =IFERROR(__xludf.DUMMYFUNCTION("""COMPUTED_VALUE"""),"台灣美光") -> 台灣美光
D5: =IFERROR(__xludf.DUMMYFUNCTION("""COMPUTED_VALUE"""),"JINS") -> JINS
D6: =IFERROR(__xludf.DUMMYFUNCTION("""COMPUTED_VALUE"""),"Google") -> Google
D7: =IFERROR(__xludf.DUMMYFUNCTION("""COMPUTED_VALUE"""),"LifeWonders") -> LifeWonders
D8: =IFERROR(__xludf.DUMMYFUNCTION("""COMPUTED_VALUE"""),"Gstar") -> Gstar
D9: =IFERROR(__xludf.DUMMYFUNCTION("""COMPUTED_VALUE"""),"聯合利華") -> 聯合利華
D10: =IFERROR(__xludf.DUMMYFUNCTION("""COMPUTED_VALUE"""),"Johnnie Walker ") -> Johnnie Walker
D11: =IFERROR(__xludf.DUMMYFUNCTION("""COMPUTED_VALUE"""),"Tapestry") -> Tapestry
D12: =IFERROR(__xludf.DUMMYFUNCTION("""COMPUTED_VALUE"""),"臺虎精釀") -> 臺虎精釀
D13: =IFERROR(__xludf.DUMMYFUNCTION("""COMPUTED_VALUE"""),"Lespark") -> Lespark
D14: =IFERROR(__xludf.DUMMYFUNCTION("""COMPUTED_VALUE"""),"吉利亞醫藥") -> 吉利亞醫藥
D15: =IFERROR(__xludf.DUMMYFUNCTION("""COMPUTED_VALUE"""),"AZ") -> AZ
D16: =IFERROR(__xludf.DUMMYFUNCTION("""COMPUTED_VALUE"""),"GSK") -> GSK
D17: =IFERROR(__xludf.DUMMYFUNCTION("""COMPUTED_VALUE"""),"必勝客") -> 必勝客
D18: =IFERROR(__xludf.DUMMYFUNCTION("""COMPUTED_VALUE"""),"犀牛盾") -> 犀牛盾
D19: =IFERROR(__xludf.DUMMYFUNCTION("""COMPUTED_VALUE"""),"默沙東") -> 默沙東
D20: =IFERROR(__xludf.DUMMYFUNCTION("""COMPUTED_VALUE"""),"TFC 臺北婦產科診所") -> TFC 臺北婦產科診所
D21: =IFERROR(__xludf.DUMMYFUNCTION("""COMPUTED_VALUE"""),"Hyve") -> Hyve
D22: =IFERROR(__xludf.DUMMYFUNCTION("""COMPUTED_VALUE"""),"疾管署") -> 疾管署
D23: =IFERROR(__xludf.DUMMYFUNCTION("""COMPUTED_VALUE"""),"Tstudio") -> Tstudio
D24: =IFERROR(__xludf.DUMMYFUNCTION("""COMPUTED_VALUE"""),"彩虹酷兒") -> 彩虹酷兒
D25: =IFERROR(__xludf.DUMMYFUNCTION("""COMPUTED_VALUE"""),"渣打銀行") -> 渣打銀行
D26: =IFERROR(__xludf.DUMMYFUNCTION("""COMPUTED_VALUE"""),"VERVE") -> VERVE
D27: =IFERROR(__xludf.DUMMYFUNCTION("""COMPUTED_VALUE"""),"IM Adult") -> IM Adult
D28: =IFERROR(__xludf.DUMMYFUNCTION("""COMPUTED_VALUE"""),"GAP") -> GAP
D29: =IFERROR(__xludf.DUMMYFUNCTION("""COMPUTED_VALUE"""),"Uber Eats") -> Uber Eats
D30: =IFERROR(__xludf.DUMMYFUNCTION("""COMPUTED_VALUE"""),"NIKE") -> NIKE
D31: =IFERROR(__xludf.DUMMYFUNCTION("""COMPUTED_VALUE"""),"TSMC") -> TSMC
D32: =IFERROR(__xludf.DUMMYFUNCTION("""COMPUTED_VALUE"""),"FNF") -> FNF
D33: =IFERROR(__xludf.DUMMYFUNCTION("""COMPUTED_VALUE"""),"可口可樂") -> 可口可樂
D34: =IFERROR(__xludf.DUMMYFUNCTION("""COMPUTED_VALUE"""),"新思科技") -> 新思科技
D35: =IFERROR(__xludf.DUMMYFUNCTION("""COMPUTED_VALUE"""),"愛群婦產科") -> 愛群婦產科
D36: =IFERROR(__xludf.DUMMYFUNCTION("""COMPUTED_VALUE"""),"辻利茶舖") -> 辻利茶舖
D37: =IFERROR(__xludf.DUMMYFUNCTION("""COMPUTED_VALUE"""),"Sagami") -> Sagami
D38: =IFERROR(__xludf.DUMMYFUNCTION("""COMPUTED_VALUE"""),"台灣百健") -> 台灣百健
D39: =IFERROR(__xludf.DUMMYFUNCTION("""COMPUTED_VALUE"""),"TENGA") -> TENGA
D40: =IFERROR(__xludf.DUMMYFUNCTION("""COMPUTED_VALUE"""),"一口純淨") -> 一口純淨
...

Sheet 保證金管理
A1: =COUNTA(A3:A525) -> 1 | B1: =COUNTA(B3:B525) -> 8 | C1: =COUNTA(C3:C525) -> 1
A2: 未付 | B2: 已付 | C2: 已退
A3: =IFERROR(__xludf.DUMMYFUNCTION("QUERY(TRANSPOSE({'31業務統計總表'!C3:J3;'31業務統計總表'!C63:J63}), ""SELECT Col1 WHERE Col2 LIKE '1. %'"", 0)"),"#N/A") -> #N/A | B3: =IFERROR(__xludf.DUMMYFUNCTION("QUERY(TRANSPOSE({'31業務統計總表'!C3:J3;'31業務統計總表'!C63:J63}), ""SELECT Col1 WHERE Col2 LIKE '2. %'"", 0)"),"諾億保經") -> 諾億保經 | C3: =IFERROR(__xludf.DUMMYFUNCTION("QUERY(TRANSPOSE({'31業務統計總表'!C3:J3;'31業務統計總表'!C63:J63}), ""SELECT Col1 WHERE Col2 LIKE '3. %'"", 0)"),"TENGA") -> TENGA
B4: =IFERROR(__xludf.DUMMYFUNCTION("""COMPUTED_VALUE"""),"台灣美光") -> 台灣美光
B5: =IFERROR(__xludf.DUMMYFUNCTION("""COMPUTED_VALUE"""),"LifeWonders") -> LifeWonders
B6: =IFERROR(__xludf.DUMMYFUNCTION("""COMPUTED_VALUE"""),"Gstar") -> Gstar
B7: =IFERROR(__xludf.DUMMYFUNCTION("""COMPUTED_VALUE"""),"Lespark") -> Lespark
B8: =IFERROR(__xludf.DUMMYFUNCTION("""COMPUTED_VALUE"""),"彩虹酷兒") -> 彩虹酷兒
B9: =IFERROR(__xludf.DUMMYFUNCTION("""COMPUTED_VALUE"""),"VERVE") -> VERVE
B10: =IFERROR(__xludf.DUMMYFUNCTION("""COMPUTED_VALUE"""),"IM Adult") -> IM Adult

Sheet 31業務統計總表
A1: 01_商業合作手冊 | C1: 單購價格 | D1: 級別限定 | E1: 最大釋出 | F1: 可售 總數量 | G1: 已售出 數量 | H1: 1 | I1: 1 | J1: 1 | K1: 2 | L1: 3 | M1: 4 | N1: 1 | O1: 2 | P1: 3 | Q1: 4 | R1: 5 | S1: 6 | T1: 7 | U1: 8 | V1: 9 | W1: 10 | X1: 11 | Y1: 12 | Z1: 1 | AA1: 2 | AB1: 3 | AC1: 4 | AD1: 5 | AE1: 6 | AF1: 1 | AG1: =AF1+1 -> 2 | AH1: =AG1+1 -> 3 | AI1: =AH1+1 -> 4 | AJ1: =AI1+1 -> 5 | AK1: 7 | AL1: =AK1+1 -> 8 | AM1: =AL1+1 -> 9 | AN1: 10 | AO1: 1 | AP1: 2 | AQ1: 3 | AR1: 4 | AS1: 5 | AT1: 6 | AU1: 7 | AV1: 1 | AW1: 1 | AX1: 2 | AY1: 3 | AZ1: 4 | BA1: 5 | BB1: 1 | BC1: 2 | BD1: 3 | BE1: 4 | BF1: 5 | BG1: 6 | BH1: 7 | BI1: 8 | BJ1: 9 | BK1: 10 | BL1: 11 | BM1: 12 | BN1: 13 | BO1: 14 | BP1: 15
A2: 級別 | H2: 白金級 | I2: 黃金級 | J2: 鈦金級 | K2: 鈦金級 | L2: 鈦金級 | M2: 鈦金級 | N2: 銀級 | O2: 銀級 | P2: 銀級 | Q2: 銀級 | R2: 銀級 | S2: 銀級 | T2: 銀級 | U2: 銀級 | V2: 銀級 | W2: 銀級 | X2: 銀級 | Y2: 銀級 | Z2: 銅級 | AA2: 銅級 | AB2: 銅級 | AC2: 銅級 | AD2: 銅級 | AE2: 銅級 | AF2: 花車 | AG2: 花車 | AH2: 花車 | AI2: 花車 | AJ2: 花車 | AK2: 花車 | AL2: 花車 | AM2: 花車 | AN2: 花車 | AO2: 單買 | AP2: 單買 | AQ2: 單買 | AR2: 單買 | AS2: 單買 | AT2: 單買 | AU2: 單買 | AV2: 市集 | AW2: 其他 | AX2: 其他 | AY2: 其他 | AZ2: 其他 | BA2: 其他 | BB2: 友善飯店 | BC2: 友善飯店 | BD2: 友善飯店 | BE2: 友善飯店 | BF2: 友善飯店 | BG2: 友善飯店 | BH2: 友善飯店 | BI2: 友善飯店 | BJ2: 友善飯店 | BK2: 友善飯店 | BL2: 友善飯店 | BM2: 友善飯店 | BN2: 友善飯店 | BO2: 友善飯店 | BP2: 友善飯店
A3: 品項 \ 贊助商 | J3: 波士頓科技 | K3: 諾億保經 | L3: 台灣美光 | M3: JINS | N3: Google | O3: LifeWonders | P3: Gstar | Q3: 聯合利華 | R3: Johnnie Walker | S3: Tapestry | T3: 臺虎精釀 | U3: Lespark | V3: 吉利亞醫藥 | W3: AZ | X3: GSK | Y3: 必勝客 | Z3: 犀牛盾 | AA3: 默沙東 | AB3: TFC 臺北婦產科診所 | AC3: Hyve | AD3: 疾管署 | AE3: Tstudio | AF3: 彩虹酷兒 | AG3: 渣打銀行 | AH3: VERVE | AI3: IM Adult | AJ3: GAP | AK3: Uber Eats | AL3: NIKE | AM3: TSMC | AN3: FNF | AO3: 可口可樂 | AP3: 新思科技 | AQ3: 愛群婦產科 | AR3: 辻利茶舖 | AS3: Sagami | AT3: 台灣百健 | AU3: 華納兄弟 | AV3: TENGA | AW3: 一口純淨 | AX3: Precision Biotics | AY3: M.A.C | AZ3: 聯名商品 | BA3: 環球影城 | BB3: 國泰萬怡 | BC3: 和逸飯店 | BD3: 大直英迪格 | BE3: 慕軒飯店 | BF3: 永安棧 | BG3: 北門世民 | BH3: amba | BI3: 君悅飯店 | BJ3: 中山雅樂軒 | BK3: 希爾頓逸林 | BL3: 南港老爺 | BM3: 小鹿文娛 | BN3: 大安伊普索 | BO3: 西門大飯店 | BP3: 金普頓大安
A4: 產業 | C4: P: 白金、G: 黃金、 T: 鈦金、S: 銀級、B: 銅級 | J4: 醫材 | K4: 金融 | L4: 科技 | M4: 生活 | N4: 科技 | O4: 遊戲 | P4: 夜店 | Q4: FMCG | R4: 酒商 | S4: 精品 | T4: 生活 | U4: 生活 | V4: 醫藥 | W4: 醫藥 | X4: 醫藥 | Y4: 速食 | Z4: 生活 | AA4: 醫藥 | AB4: 醫療 | AC4: 科技 | AD4: 政府 | AE4: 生活 | AF4: NGO | AG4: 金融 | AH4: 服飾 | AI4: 成人 | AJ4: 服飾 | AK4: 生活 | AL4: 運動 | AM4: 科技 | AN4: 基金會 | AO4: 生活 | AP4: 科技 | AQ4: 醫療 | AR4: 食品 | AS4: 生活 | AT4: 醫藥 | AU4: 影視 | AV4: 生活 | AW4: 生活 | AX4: 生活 | AY4: 彩妝 | BB4: A | BC4: A | BD4: B | BE4: B | BF4: B | BG4: B | BH4: B | BI4: B | BJ4: C | BK4: C | BL4: C | BM4: C | BN4: C | BO4: C | BP4: C
A5: 業務窗口 | J5: 群、Lisa | K5: 群 | L5: 群、Alonso | M5: 群、Timmy | N5: Jerry | O5: Alonso | P5: 達達 | Q5: Jerry | R5: Joyce | S5: 踢米 | T5: 達達 | V5: 踢米 | W5: 小賴 | X5: Alonso | Y5: Scott | Z5: Joyce | AA5: 小賴 | AB5: 小賴 | AC5: 深紅 | AD5: 群 | AE5: 群
A6: 級 別 專 屬 項 目 | B6: 有條件競業排他條款 | C6: -- | D6: P、G | E6: 4 | F6: =IF(E6>0, E6-G6, "-") -> 4 | G6: =SUM(J6:BP6) -> 0
B7: 行前記者會之友善企業發言權 | C7: -- | D7: P | E7: 1 | F7: =IF(E7>0, E7-G7, "-") -> 1 | G7: =SUM(J7:BP7) -> 0
B8: 行前記者會之會後媒體採訪權 | C8: -- | D8: P | E8: 1 | F8: =IF(E8>0, E8-G8, "-") -> 1 | G8: =SUM(J8:BP8) -> 0
B9: 行前記者會之友善發言影片 | C9: -- | D9: P、G | E9: 4 | F9: =IF(E9>0, E9-G9, "-") -> 4 | G9: =SUM(J9:BP9) -> 0
B10: 行前記者會之新聞稿置入 | C10: -- | D10: P | E10: 1 | F10: =IF(E10>0, E10-G10, "-") -> 1 | G10: =SUM(J10:BP10) -> 0
B11: 行前記者會之新聞稿企業名置入 | C11: -- | D11: P、G、T | E11: 9 | F11: =IF(E11>0, E11-G11, "-") -> 9 | G11: =SUM(J11:BP11) -> 0
B12: 活動當日舞台致詞權 | C12: -- | D12: P | E12: 1 | F12: =IF(E12>0, E12-G12, "-") -> 1 | G12: =SUM(J12:BP12) -> 0
B13: 活動當日媒體受訪權 | C13: -- | D13: P | E13: 1 | F13: =IF(E13>0, E13-G13, "-") -> 1 | G13: =SUM(J13:BP13) -> 0
B14: 活動當日主持人唱名 | C14: -- | D14: P、G、T | E14: 9 | F14: =IF(E14>0, E14-G14, "-") -> 9 | G14: =SUM(J14:BP14) -> 0
B15: 活動現場 LOGO 曝光 | C15: -- | D15: P、G、T、S | E15: -1 | F15: =IF(E15>0, E15-G15, "-") -> - | G15: =SUM(J15:BP15) -> 0
B16: 線上 LOGO 曝光 | C16: -- | D16: P、G、T、S、B | E16: -1 | F16: =IF(E16>0, E16-G16, "-") -> - | G16: =SUM(J16:BP16) -> 0
B17: 主視覺使用權 | C17: -- | D17: P、G | E17: -1 | F17: =IF(E17>0, E17-G17, "-") -> - | G17: =SUM(J17:BP17) -> 0
A18: S 區 | B18: 首位商業遊行花車路權 | C18: 200000 | E18: 2 | F18: =IF(E18>0, E18-G18, "-") -> 2 | G18: =SUM(H18:BP18) -> 0
B19: 企業品牌空間使用權 A 位 | C19: 250000 | E19: 2 | F19: =IF(E19>0, E19-G19, "-") -> 0 | G19: =SUM(H19:BP19) -> 2 | AH19: 1 | AO19: 1
B20: 舞台音響看板露出 | C20: 250000 | E20: 2 | F20: =IF(E20>0, E20-G20, "-") -> 2 | G20: =SUM(H20:BP20) -> 0
B21: 轉播螢幕看板露出 | C21: 200000 | E21: 2 | F21: =IF(E21>0, E21-G21, "-") -> 1 | G21: =SUM(H21:BP21) -> 1 | M21: 1
B22: 活動打卡牆（大） | C22: 300000 | E22: 2 | F22: 2 | G22: =SUM(H22:BP22) -> 0
B23: 活動打卡牆（中） | C23: 220000 | E23: 2 | F23: =IF(E23>0, E23-G23, "-") -> 2 | G23: =SUM(H23:BP23) -> 0
A24: A 區 | B24: 一般商業遊行花車路權 | C24: 120000 | E24: 28 | F24: =IF(E24>0, E24-G24, "-") -> 8 | G24: =SUM(H24:BP24) -> 20 | K24: 1 | N24: 1 | P24: 1 | Q24: 1 | S24: 1 | T24: 1 | U24: 1 | V24: 1 | W24: 1 | X24: 1 | Y24: 1 | AF24: 1 | AG24: 1 | AH24: 1 | AI24: 1 | AJ24: 1 | AK24: 1 | AL24: 1 | AM24: 1 | AN24: 1
B25: 企業品牌空間使用 B 位 | C25: 150000 | E25: 8 | F25: =IF(E25>0, E25-G25, "-") -> 6 | G25: =SUM(H25:BP25) -> 2 | J25: 1 | R25: 1
B26: 活動打卡牆（小） | C26: 150000 | E26: 3 | F26: =IF(E26>0, E26-G26, "-") -> 2 | G26: =SUM(H26:BP26) -> 1 | O26: 1
A27: B 區 | B27: 官方網站企業版位露出 B 位，每廠商限選1 | C27: 50000 | E27: 16 | F27: =IF(E27>0, E27-G27, "-") -> 0 | G27: =SUM(H27:BP27) -> 16 | J27: 1 | K27: 1 | L27: 1 | M27: 1 | N27: 1 | O27: 1 | P27: 1 | Q27: 1 | S27: 1 | U27: 1 | V27: 1 | X27: 1 | AA27: 1 | AB27: 1 | AC27: 1 | AD27: 1
B28: 10 月官方 FB 貼文置入合作 | C28: 45000 | E28: 28 | F28: =IF(E28>0, E28-G28, "-") -> 16 | G28: =SUM(H28:BP28) -> 12 | J28: 1 | K28: 1 | L28: 1 | M28: 2 | Q28: 1 | W28: 1 | X28: 1 | Y28: 1 | Z28: 1 | AC28: 1 | AQ28: 1
B29: 10 月官方 IG 貼文置入合作 | C29: 45000 | E29: 28 | F29: =IF(E29>0, E29-G29, "-") -> 12 | G29: =SUM(H29:BP29) -> 16 | J29: 1 | K29: 1 | L29: 1 | M29: 1 | N29: 1 | P29: 1 | R29: 1 | S29: 1 | T29: 1 | U29: 1 | V29: 1 | W29: 1 | Z29: 1 | AA29: 1 | AD29: 1 | AS29: 1
B30: 10 月官方 IG Reels 置入合作 | C30: 45000 | E30: 28 | F30: =IF(E30>0, E30-G30, "-") -> 19 | G30: =SUM(H30:BP30) -> 9 | J30: 1 | K30: 1 | L30: 1 | O30: 1 | R30: 1 | T30: 1 | W30: 1 | Y30: 1 | AB30: 1
A31: C 區 | B31: 活動現場看板露出 | C31: 35000 | E31: 28 | F31: =IF(E31>0, E31-G31, "-") -> 0 | G31: =SUM(H31:BP31) -> 28 | J31: 1 | K31: 1 | L31: 1 | M31: 1 | N31: 1 | O31: 3 | P31: 1 | Q31: 1 | R31: 1 | S31: 1 | T31: 1 | U31: 1 | V31: 3 | W31: 1 | X31: 1 | Y31: 1 | Z31: 1 | AA31: 1 | AC31: 1 | AD31: 1 | AQ31: 1 | AX31: 1 | AZ31: 2
B32: 11 月官方 FB 貼文置入合作 | C32: 30000 | E32: 20 | F32: =IF(E32>0, E32-G32, "-") -> 13 | G32: =SUM(H32:BP32) -> 7 | K32: 1 | P32: 1 | U32: 1 | V32: 1 | X32: 1 | Y32: 1 | AB32: 1
B33: 11 月官方 IG 貼文置入合作 | C33: 30000 | E33: 20 | F33: =IF(E33>0, E33-G33, "-") -> 7 | G33: =SUM(H33:BP33) -> 13 | J33: 1 | K33: 1 | L33: 1 | M33: 1 | N33: 1 | P33: 1 | Q33: 1 | R33: 1 | S33: 1 | T33: 1 | V33: 1 | W33: 1 | X33: 1
B34: 11 月官方 IG Reels 置入合作 | C34: 30000 | E34: 20 | F34: =IF(E34>0, E34-G34, "-") -> 8 | G34: =SUM(H34:BP34) -> 12 | J34: 1 | L34: 1 | M34: 1 | N34: 1 | Q34: 1 | R34: 1 | S34: 1 | T34: 1 | U34: 1 | V34: 1 | W34: 1 | Y34: 1
A35: D 區 | B35: 轉播螢幕之輪播影片置入（限選 2） | C35: 18000 | E35: 40 | F35: =IF(E35>0, E35-G35, "-") -> 16 | G35: =SUM(H35:BP35) -> 24 | K35: 1 | L35: 1 | M35: 2 | N35: 1 | O35: 2 | Q35: 2 | R35: 1 | S35: 1 | V35: 1 | W35: 1 | X35: 1 | Y35: 1 | AA35: 1 | AC35: 1 | AD35: 1 | AS35: 1 | AU35: 2 | AY35: 1 | BA35: 2
B36: 活動手冊 A6 版位露出（限選 1） | C36: 25000 | E36: 24 | F36: =IF(E36>0, E36-G36, "-") -> 4 | G36: =SUM(H36:BP36) -> 20 | J36: 1 | K36: 1 | L36: 1 | M36: 1 | N36: 1 | P36: 1 | U36: 1 | W36: 1 | X36: 1 | Z36: 1 | AB36: 1 | AC36: 1 | AD36: 1 | AE36: 2 | AQ36: 1 | AR36: 1 | AW36: 1 | AX36: 1 | AY36: 1
B37: 彩虹市集 - 獨立棚（限選 2） | C37: 20000 | E37: 80 | F37: =IF(E37>0, E37-G37, "-") -> 56 | G37: =SUM(H37:BP37) -> 24 | J37: 2 | L37: 2 | O37: 2 | P37: 1 | Q37: 2 | R37: 1 | S37: 1 | T37: 2 | U37: 1 | V37: 2 | Y37: 1 | AB37: 1 | AE37: 3 | AV37: 1 | AW37: 2
B38: FB+IG 社群限時動態置入合作（10/18-10/23） | C38: -- | E38: 18 | F38: =IF(E38>0, E38-G38, "-") -> 2 | G38: =SUM(H38:BP38) -> 16 | J38: 1 | K38: 2 | L38: 1 | M38: 1 | N38: 1 | P38: 1 | R38: 1 | S38: 1 | T38: 1 | U38: 1 | W38: 1 | X38: 1 | Y38: 1 | Z38: 1 | AA38: 1
A39: E 區 | B39: 官方網站企業版位露出 C 位 | C39: 20000 | E39: 18 | F39: =IF(E39>0, E39-G39, "-") -> 4 | G39: =SUM(H39:BP39) -> 14 | J39: 1 | K39: 1 | M39: 1 | N39: 1 | O39: 2 | P39: 1 | Q39: 1 | R39: 1 | U39: 1 | W39: 1 | X39: 1 | Y39: 1 | AT39: 1
B40: 9 月官方 FB 貼文置入合作 | C40: 20000 | E40: 15 | F40: =IF(E40>0, E40-G40, "-") -> 5 | G40: =SUM(H40:BP40) -> 10 | K40: 1 | L40: 1 | M40: 1 | P40: 1 | T40: 1 | U40: 1 | X40: 1 | Z40: 1 | AA40: 1 | AD40: 1
...

Sheet 廠商聯絡資料
A1: 小組長 | B1: 級別 | C1: 廠商 | D1: 廠商聯絡人 | E1: 廠商 email | F1: 備註
A2: =IFERROR(__xludf.DUMMYFUNCTION("QUERY(TRANSPOSE('31業務統計總表'!F2:J4),""SELECT Col4, Col1, Col2 WHERE Col3 <> '' ORDER BY Col4"")"),"#VALUE!") -> #VALUE! | D2: Vanessa | E2: Vanessa.Kuo@bsci.com

Sheet 市集

Sheet 33收入總表
A1: 款 | B1: 項 | C1: 項目 | D1: 實際資訊 | E1: 實際資訊 | I1: 預估資訊 | P1: 對照資訊 | R1: 備註
D2: 廠商名稱 | E2: 實際數量 | F2: 早鳥價 | G2: 原價 | H2: 商業組窗口 | I2: 方案一 數量 | J2: 方案二 數量 | K2: 方案三 數量 | L2: 方案三 廠商 | M2: 方案一 金額 | N2: 方案二 金額 | O2: 方案三 金額 | P2: 數量 | Q2: 金額
A4: 1 | D4: 級別 | F4: =F5+F8+F11+F20+F36+F69+F81 -> 0 | G4: =G5+G8+G11+G20 -> 0 | M4: =M5+M8+M11+M20 -> 0 | N4: =N5+N8+N11+N20 -> #REF! | O4: =O5+O8+O11+O20 -> 3300000
B5: 1 | D5: 白金級 | E5: =SUM(E6:E7) -> 0 | F5: =SUM(F6:F7) -> 0 | G5: =SUM(G6:G7) -> 0 | I5: =SUM(I6:I7) -> 0 | J5: =SUM(J6:J7) -> 1 | K5: =SUM(K6:K7) -> 1 | M5: =SUM(M6:M7) -> 0 | N5: =SUM(N6:N7) -> #REF! | O5: =SUM(O6:O7) -> 1000000
C6: =ROW()-ROW(B$5) -> 1 | E6: =COUNTA(D6) -> 0 | I6: 0 | J6: 1 | K6: 1 | L6: GILEAD | N6: =J6*'30品項-價格'!$E$2 -> #REF! | O6: =1000000 -> 1000000
C7: =ROW()-ROW(B$5) -> 2 | E7: 0 | I7: 0
B8: 2 | D8: 黃金級 | E8: =SUM(E9:E10) -> 0 | F8: =SUM(F9:F10) -> 0 | G8: =SUM(G9:G10) -> 0 | I8: =SUM(I9:I10) -> 0 | J8: =SUM(J9:J10) -> 2 | K8: =SUM(K9:K10) -> 2 | M8: =SUM(M9:M10) -> 0 | N8: =SUM(N9:N10) -> #REF! | O8: =SUM(O9:O10) -> 1400000
C9: =ROW()-ROW(B$8) -> 1 | E9: =COUNTA(D9) -> 0 | I9: 0 | J9: 1 | K9: 1 | L9: DIKE | M9: 0 | N9: =J9*'30品項-價格'!$H$2 -> #REF! | O9: 700000
C10: =ROW()-ROW(B$8) -> 2 | E10: 0 | I10: 0 | J10: 1 | K10: 1 | L10: ASML | N10: =J10*'30品項-價格'!$H$2 -> #REF! | O10: 700000
B11: 3 | D11: 白銀級 | E11: =SUM(E12:E19) -> 0 | F11: =SUM(F12:F15) -> 0 | G11: =SUM(G12:G15) -> 0 | I11: =SUM(I12:I19) -> 0 | J11: =SUM(J12:J15) -> 4 | K11: =SUM(K12:K15) -> 4 | M11: =SUM(M12:M15) -> 0 | N11: =SUM(N12:N15) -> #REF! | O11: =SUM(O12:O15) -> 900000
C12: =ROW()-ROW(B$11) -> 1 | E12: =COUNTA(D12) -> 0 | I12: 0 | J12: 1 | K12: 1 | L12: APPLE | N12: =J12*'30品項-價格'!$K$2 -> #REF! | O12: 300000
C13: =ROW()-ROW(B$11) -> 2 | E13: =COUNTA(D13) -> 0 | I13: 0 | J13: 1 | K13: 1 | L13: AZ | N13: =J13*'30品項-價格'!$K$2 -> #REF! | O13: 300000
C14: =ROW()-ROW(B$11) -> 3 | E14: =COUNTA(D14) -> 0 | I14: 0 | J14: 1 | K14: 1 | N14: =J14*'30品項-價格'!$K$2 -> #REF! | O14: 300000
C15: =ROW()-ROW(B$11) -> 4 | E15: =COUNTA(D15) -> 0 | I15: 0 | J15: 1 | K15: 1 | N15: =J15*'30品項-價格'!$K$2 -> #REF!
C16: 5 | E16: 0 | I16: 0
C17: 6 | E17: 0 | I17: 0
C18: 7 | E18: 0 | I18: 0
C19: 8 | E19: 0 | I19: 0
B20: 4 | D20: 銀級 | E20: =SUM(E21:E35) -> 0 | F20: =SUM(F21:F35) -> 0 | G20: =SUM(G21:G35) -> 0 | I20: =SUM(I21:I35) -> 0 | J20: =SUM(J21:J30) -> 0 | K20: =SUM(K21:K30) -> 0 | M20: =SUM(M21:M35) -> 0 | N20: =SUM(N21:N30) -> 0 | O20: =SUM(O21:O30) -> 0
C21: =ROW()-ROW(B$20) -> 1 | E21: =COUNTA(D21) -> 0 | I21: 0
C22: =ROW()-ROW(B$20) -> 2 | E22: =COUNTA(D22) -> 0 | I22: 0
C23: =ROW()-ROW(B$20) -> 3 | E23: =COUNTA(D23) -> 0 | I23: 0
C24: =ROW()-ROW(B$20) -> 4 | E24: =COUNTA(D24) -> 0 | I24: 0
C25: =ROW()-ROW(B$20) -> 5 | E25: =COUNTA(D25) -> 0 | I25: 0
C26: =ROW()-ROW(B$20) -> 6 | E26: =COUNTA(D26) -> 0 | I26: 0
C27: =ROW()-ROW(B$20) -> 7 | E27: =COUNTA(D27) -> 0 | I27: 0
C28: =ROW()-ROW(B$20) -> 8 | E28: =COUNTA(D28) -> 0 | I28: 0
C29: =ROW()-ROW(B$20) -> 9 | E29: =COUNTA(D29) -> 0 | I29: 0
C30: =ROW()-ROW(B$20) -> 10 | E30: 0 | I30: 0
C31: =ROW()-ROW(B$20) -> 11 | E31: =COUNTA(D31) -> 0 | I31: 0
C32: =ROW()-ROW(B$20) -> 12 | E32: =COUNTA(D32) -> 0 | I32: 0
C33: =ROW()-ROW(B$20) -> 13 | E33: =COUNTA(D33) -> 0 | I33: 0
C34: =ROW()-ROW(B$20) -> 14 | E34: 0 | I34: 0
C35: =ROW()-ROW(B$20) -> 15 | E35: 0 | I35: 0
A36: 2 | D36: 商業車 | E36: =E37+E40 -> 2 | F36: =F37+F40 -> 0 | G36: =G37+G40 -> 0
B37: 1 | D37: 遊行花車權利-商業車首位 | E37: =SUM(E38:E39) -> 2 | F37: =SUM(F38:F39) -> 0 | G37: =SUM(G38:G39) -> 0 | I37: =SUM(I38:I39) -> 2
C38: =ROW()-ROW(B$37) -> 1 | E38: =COUNTA(#REF!) -> 1 | I38: 1
C39: =ROW()-ROW(B$37) -> 2 | E39: =COUNTA(#REF!) -> 1 | I39: 1
B40: 2 | D40: 遊行花車權利-商業車 | E40: =SUM(E41:E68) -> 0 | F40: =SUM(F41:F62) -> 0 | G40: =SUM(G41:G62) -> 0 | I40: =SUM(I41:I68) -> 0
C41: =ROW()-ROW(B$40) -> 1 | E41: 0 | I41: 0
...

Sheet 321 贊助商收款明細
A1: 類型 | B1: 贊助商名稱 | C1: 業務窗口 | D1: 金額 | E1: 保證金 | F1: 預期收款日 | G1: 實際收款日
A2: =IFERROR(__xludf.DUMMYFUNCTION("QUERY({ QUERY(TRANSPOSE('31業務統計總表'!G2:N5), ""SELECT Col1, Col2, Col4"", 0); QUERY(IMPORTRANGE(""https://docs.google.com/spreadsheets/d/14Gtvwy6lCGjn7263pvSyPPPzWEm88WpAFRYb3LxfKLg/"", ""'21彩虹市集_商業攤'!A:V""), ""SELECT '彩虹市集-商業攤', Col1, '小盛' WHERE Col22 = TR"&"UE"", 0); QUERY(IMPORTRANGE(""https://docs.google.com/spreadsheets/d/14Gtvwy6lCGjn7263pvSyPPPzWEm88WpAFRYb3LxfKLg/"", ""'22彩虹市集_NGO攤'!A:A""), ""SELECT '彩虹市集-NGO攤', Col1, '小艾' WHERE Col1 <>''"", 0) }, ""SELECT * WHERE Col2 <> ''"", 0)"),"#VALUE!") -> #VALUE!

Sheet 322 帳戶收款明細
A1: 帳戶 | B1: 日期 | C1: 金額 | D1: 類型 | E1: 贊助商
D2: 白金級
D3: 白金級
